Traceback (most recent call last):
  File "/Users/peterbanyas/Desktop/ECE 661/Project 661/ece661-GAN-project/analysis/inferencetime.py", line 30, in <module>
    PTH_pix2pix_UNet = wandb.restore("generator_epoch_100.pth", run_path="michael-scutari-duke-university/pix2pix-map2sat/runs/jwo7nugf")
  File "/Library/Frameworks/Python.framework/Versions/3.10/lib/python3.10/site-packages/wandb/sdk/wandb_run.py", line 4093, in restore
    raise ValueError(f"File {name} not found in {run_path or root}.")
ValueError: File generator_epoch_100.pth not found in michael-scutari-duke-university/pix2pix-map2sat/runs/jwo7nugf.
